Workbook

Sheet Model_Calculations
A1: NBD Model — Bills vs Broncos (Combined Threads)
A2: Left-truncated at x=1: lurkers (x=0) are unobserved. All statistics are conditional on participation.
A4: SECTION A — Raw Histogram Data (full tail, from histogram CSV)
A5: Row | B5: x (# comments) | C5: Actual Count (n_x)
A6: 1 | B6: 1 | C6: 5369
A7: 2 | B7: 2 | C7: 2213
A8: 3 | B8: 3 | C8: 1186
A9: 4 | B9: 4 | C9: 803
A10: 5 | B10: 5 | C10: 545
A11: 6 | B11: 6 | C11: 372
A12: 7 | B12: 7 | C12: 314
A13: 8 | B13: 8 | C13: 258
A14: 9 | B14: 9 | C14: 209
A15: 10 | B15: 10 | C15: 149
A16: 11 | B16: 11 | C16: 136
A17: 12 | B17: 12 | C17: 138
... A97: 92 | B97: 162 | C97: 1
A98: TOTAL | C98: =SUM(C6:C97) -> 12791
A100: SECTION B — Solver Inputs + λ
A101: r | B101: 0.96754919
A102: α | B102: 0.20426015 | D102: Poisson PMF (No Observed Zeroes) | F102: NBD PMF (No Observed Zeroes)
A103: λ | B103: =SUMPRODUCT(B6:B97, C6:C97) / C98 -> 4.786256 | D103: =EXP(-$B$103) -> 0.0083436379 | F103: =($B$102/($B$102+1))^$B$101 -> 0.17966682
A105: SECTION C — Full Histogram with Model Probabilities
A106: x | B106: Actual Count (n_x) | C106: Poisson PMF P(X=x|λ) | D106: Poisson Expected | E106: NBD PMF P(X=x|r,α) | F106: NBD Expected | G106: Poisson LL | H106: NBD LL | I106: Actual Proportion
A107: 1 | B107: 5369 | C107: =($B$103/1) * D103 -> 0.039934787 | D107: =C107*$C$98 -> 510.80585 | E107: =(($B$101)/(1*($B$102+1))) * F103 -> 0.14435127 | F107: =E107*$C$98 -> 1846.3971 | G107: =IF(C107>0, B107*LN(C107), 0) -> -17290.905 | H107: =IF(E107>0, B107*LN(E107), 0) -> -10391.729 | I107: =B107/C98 -> 0.41974826
A108: 2 | B108: 2213 | C108: =($B$103/A108) * C107 -> 0.095569055 | D108: =C108*$C$98 -> 1222.4238 | E108: =(($B$101 + A108 - 1)/(A108*($B$102+1))) * E107 -> 0.11792229 | F108: =E108*$C$98 -> 1508.344 | G108: =IF(C108>0, B108*LN(C108), 0) -> -5195.9164 | H108: =IF(E108>0, B108*LN(E108), 0) -> -4730.7953 | I108: =B108/C98 -> 0.17301227
A109: 3 | B109: 1186 | C109: =($B$103/A109) * C108 -> 0.15247265 | D109: =C109*$C$98 -> 1950.2777 | E109: =(($B$101 + A109 - 1)/(A109*($B$102+1))) * E108 -> 0.096861737 | F109: =E109*$C$98 -> 1238.9585 | G109: =IF(C109>0, B109*LN(C109), 0) -> -2230.5932 | H109: =IF(E109>0, B109*LN(E109), 0) -> -2768.6823 | I109: =B109/C98 -> 0.092721445
A110: 4 | B110: 803 | C110: =($B$103/A110) * C109 -> 0.18244329 | D110: =C110*$C$98 -> 2333.6321 | E110: =(($B$101 + A110 - 1)/(A110*($B$102+1))) * E109 -> 0.079780043 | F110: =E110*$C$98 -> 1020.4665 | G110: =IF(C110>0, B110*LN(C110), 0) -> -1366.1567 | H110: =IF(E110>0, B110*LN(E110), 0) -> -2030.371 | I110: =B110/C98 -> 0.062778516
A111: 5 | B111: 545 | C111: =($B$103/A111) * C110 -> 0.17464405 | D111: =C111*$C$98 -> 2233.8721 | E111: =(($B$101 + A111 - 1)/(A111*($B$102+1))) * E110 -> 0.065818218 | F111: =E111*$C$98 -> 841.88083 | G111: =IF(C111>0, B111*LN(C111), 0) -> -951.02792 | H111: =IF(E111>0, B111*LN(E111), 0) -> -1482.8679 | I111: =B111/C98 -> 0.042608084
A112: 6 | B112: 372 | C112: =($B$103/A112) * C111 -> 0.13931519 | D112: =C112*$C$98 -> 1781.9806 | E112: =(($B$101 + A112 - 1)/(A112*($B$102+1))) * E111 -> 0.054358888 | F112: =E112*$C$98 -> 695.30453 | G112: =IF(C112>0, B112*LN(C112), 0) -> -733.21808 | H112: =IF(E112>0, B112*LN(E112), 0) -> -1083.3187 | I112: =B112/C98 -> 0.029082949
A113: 7 | B113: 314 | C113: =($B$103/A113) * C112 -> 0.09525688 | D113: =C113*$C$98 -> 1218.4308 | E113: =(($B$101 + A113 - 1)/(A113*($B$102+1))) * E112 -> 0.044929569 | F113: =E113*$C$98 -> 574.69411 | G113: =IF(C113>0, B113*LN(C113), 0) -> -738.2699 | H113: =IF(E113>0, B113*LN(E113), 0) -> -974.23497 | I113: =B113/C98 -> 0.024548511
A114: 8 | B114: 258 | C114: =($B$103/A114) * C113 -> 0.056990476 | D114: =C114*$C$98 -> 728.96518 | E114: =(($B$101 + A114 - 1)/(A114*($B$102+1))) * E113 -> 0.037157518 | F114: =E114*$C$98 -> 475.28182 | G114: =IF(C114>0, B114*LN(C114), 0) -> -739.13675 | H114: =IF(E114>0, B114*LN(E114), 0) -> -849.488 | I114: =B114/C98 -> 0.020170432
A115: 9 | B115: 209 | C115: =($B$103/A115) * C114 -> 0.03030789 | D115: =C115*$C$98 -> 387.66822 | E115: =(($B$101 + A115 - 1)/(A115*($B$102+1))) * E114 -> 0.030743807 | F115: =E115*$C$98 -> 393.24403 | G115: =IF(C115>0, B115*LN(C115), 0) -> -730.73657 | H115: =IF(E115>0, B115*LN(E115), 0) -> -727.75194 | I115: =B115/C98 -> 0.016339614
A116: 10 | B116: 149 | C116: =($B$103/A116) * C115 -> 0.014506132 | D116: =C116*$C$98 -> 185.54793 | E116: =(($B$101 + A116 - 1)/(A116*($B$102+1))) * E115 -> 0.025446363 | F116: =E116*$C$98 -> 325.48443 | G116: =IF(C116>0, B116*LN(C116), 0) -> -630.74439 | H116: =IF(E116>0, B116*LN(E116), 0) -> -547.00619 | I116: =B116/C98 -> 0.011648816
A117: 11 | B117: 136 | C117: =($B$103/A117) * C116 -> 0.0063118236 | D117: =C117*$C$98 -> 80.734535 | E117: =(($B$101 + A117 - 1)/(A117*($B$102+1))) * E116 -> 0.021067951 | F117: =E117*$C$98 -> 269.48016 | G117: =IF(C117>0, B117*LN(C117), 0) -> -688.88497 | H117: =IF(E117>0, B117*LN(E117), 0) -> -524.96031 | I117: =B117/C98 -> 0.010632476
A118: 12 | B118: 138 | C118: =($B$103/A118) * C117 -> 0.0025175003 | D118: =C118*$C$98 -> 32.201346 | E118: =(($B$101 + A118 - 1)/(A118*($B$102+1))) * E117 -> 0.017447209 | F118: =E118*$C$98 -> 223.16725 | G118: =IF(C118>0, B118*LN(C118), 0) -> -825.85946 | H118: =IF(E118>0, B118*LN(E118), 0) -> -558.70343 | I118: =B118/C98 -> 0.010788836
A119: 13 | B119: 99 | C119: =($B$103/A119) * C118 -> 0.00092687698 | D119: =C119*$C$98 -> 11.855683 | E119: =(($B$101 + A119 - 1)/(A119*($B$102+1))) * E118 -> 0.014451742 | F119: =E119*$C$98 -> 184.85223 | G119: =IF(C119>0, B119*LN(C119), 0) -> -691.38528 | H119: =IF(E119>0, B119*LN(E119), 0) -> -419.45709 | I119: =B119/C98 -> 0.0077398171
A120: 14 | B120: 89 | C120: =($B$103/A120) * C119 -> 0.00031687646 | D120: =C120*$C$98 -> 4.0531668 | E120: =(($B$101 + A120 - 1)/(A120*($B$102+1))) * E119 -> 0.011972699 | F120: =E120*$C$98 -> 153.14279 | G120: =IF(C120>0, B120*LN(C120), 0) -> -717.07287 | H120: =IF(E120>0, B120*LN(E120), 0) -> -393.83624 | I120: =B120/C98 -> 0.0069580174
A121: 15 | B121: 93 | C121: =($B$103/A121) * C120 -> 0.00010111012 | D121: =C121*$C$98 -> 1.2932996 | E121: =(($B$101 + A121 - 1)/(A121*($B$102+1))) * E120 -> 0.0099204454 | F121: =E121*$C$98 -> 126.89242 | G121: =IF(C121>0, B121*LN(C121), 0) -> -855.53493 | H121: =IF(E121>0, B121*LN(E121), 0) -> -429.02364 | I121: =B121/C98 -> 0.0072707372
A122: 16 | B122: 70 | C122: =($B$103/A122) * C121 -> 3.0246183e-05 | D122: =C122*$C$98 -> 0.38687893 | E122: =(($B$101 + A122 - 1)/(A122*($B$102+1))) * E121 -> 0.008221085 | F122: =E122*$C$98 -> 105.1559 | G122: =IF(C122>0, B122*LN(C122), 0) -> -728.42984 | H122: =IF(E122>0, B122*LN(E122), 0) -> -336.07372 | I122: =B122/C98 -> 0.0054725979
...

Sheet Observed_vs_Expected
A1: Observed vs Expected — Bills vs Broncos (Combined Threads) | P1: x | Q1: Actual Count (n_x) | R1: Poisson Expected | S1: NBD Expected
A2: Left-truncated at x=1. Proportions conditional on x≥1. Bars = Observed; Line = NBD Expected. | P2: 1 | Q2: 5369 | R2: 510.80585 | S2: 1846.3971
P3: 2 | Q3: 2213 | R3: 1222.4238 | S3: 1508.344
A4: x | B4: Observed Proportion | C4: NBD Expected Proportion | D4: Poisson Expected Proportion | P4: 3 | Q4: 1186 | R4: 1950.2777 | S4: 1238.9585
A5: 1 | B5: =Model_Calculations!I107 -> 0.41974826 | C5: =Model_Calculations!E107/Model_Calculations!E200 -> 0.17596664 | D5: =Model_Calculations!C107/Model_Calculations!C199 -> 0.040270791 | P5: 4 | Q5: 803 | R5: 2333.6321 | S5: 1020.4665
A6: 2 | B6: =Model_Calculations!I108 -> 0.17301227 | C6: =Model_Calculations!E108/Model_Calculations!E200 -> 0.14374926 | D6: =Model_Calculations!C108/Model_Calculations!C199 -> 0.096373158 | P6: 5 | Q6: 545 | R6: 2233.8721 | S6: 841.88083
A7: 3 | B7: =Model_Calculations!I109 -> 0.092721445 | C7: =Model_Calculations!E109/Model_Calculations!E200 -> 0.1180761 | D7: =Model_Calculations!C109/Model_Calculations!C199 -> 0.15375553 | P7: 6 | Q7: 372 | R7: 1781.9806 | S7: 695.30453
A8: 4 | B8: =Model_Calculations!I110 -> 0.062778516 | C8: =Model_Calculations!E110/Model_Calculations!E200 -> 0.097253222 | D8: =Model_Calculations!C110/Model_Calculations!C199 -> 0.18397833 | P8: 7 | Q8: 314 | R8: 1218.4308 | S8: 574.69411
A9: 5 | B9: =Model_Calculations!I111 -> 0.042608084 | C9: =Model_Calculations!E111/Model_Calculations!E200 -> 0.080233522 | D9: =Model_Calculations!C111/Model_Calculations!C199 -> 0.17611348 | P9: 8 | Q9: 258 | R9: 728.96518 | S9: 475.28182
A10: 6 | B10: =Model_Calculations!I112 -> 0.029082949 | C10: =Model_Calculations!E112/Model_Calculations!E200 -> 0.066264404 | D10: =Model_Calculations!C112/Model_Calculations!C199 -> 0.14048737 | P10: 9 | Q10: 209 | R10: 387.66822 | S10: 393.24403
A11: 7 | B11: =Model_Calculations!I113 -> 0.024548511 | C11: =Model_Calculations!E113/Model_Calculations!E200 -> 0.054769904 | D11: =Model_Calculations!C113/Model_Calculations!C199 -> 0.096058356 | P11: 10 | Q11: 149 | R11: 185.54793 | S11: 325.48443
A12: 8 | B12: =Model_Calculations!I114 -> 0.020170432 | C12: =Model_Calculations!E114/Model_Calculations!E200 -> 0.045295643 | D12: =Model_Calculations!C114/Model_Calculations!C199 -> 0.057469985 | P12: 11 | Q12: 136 | R12: 80.734535 | S12: 269.48016
A13: 9 | B13: =Model_Calculations!I115 -> 0.016339614 | C13: =Model_Calculations!E115/Model_Calculations!E200 -> 0.037477221 | D13: =Model_Calculations!C115/Model_Calculations!C199 -> 0.030562895 | P13: 12 | Q13: 138 | R13: 32.201346 | S13: 223.16725
A14: 10 | B14: =Model_Calculations!I116 -> 0.011648816 | C14: =Model_Calculations!E116/Model_Calculations!E200 -> 0.031019547 | D14: =Model_Calculations!C116/Model_Calculations!C199 -> 0.014628184 | P14: 13 | Q14: 99 | R14: 11.855683 | S14: 184.85223
A15: 11 | B15: =Model_Calculations!I117 -> 0.010632476 | C15: =Model_Calculations!E117/Model_Calculations!E200 -> 0.025682189 | D15: =Model_Calculations!C117/Model_Calculations!C199 -> 0.0063649303 | P15: 14 | Q15: 89 | R15: 4.0531668 | S15: 153.14279
A16: 12 | B16: =Model_Calculations!I118 -> 0.010788836 | C16: =Model_Calculations!E118/Model_Calculations!E200 -> 0.021268443 | D16: =Model_Calculations!C118/Model_Calculations!C199 -> 0.0025386821 | P16: 15 | Q16: 93 | R16: 1.2932996 | S16: 126.89242
A17: 13 | B17: =Model_Calculations!I119 -> 0.0077398171 | C17: =Model_Calculations!E119/Model_Calculations!E200 -> 0.017616918 | D17: =Model_Calculations!C119/Model_Calculations!C199 -> 0.00093467557 | P17: 16 | Q17: 70 | R17: 0.38687893 | S17: 105.1559
A18: 14 | B18: =Model_Calculations!I120 -> 0.0069580174 | C18: =Model_Calculations!E120/Model_Calculations!E200 -> 0.014594922 | D18: =Model_Calculations!C120/Model_Calculations!C199 -> 0.00031954261 | P18: 17 | Q18: 54 | R18: 0.10892362 | S18: 87.153235
A19: 15 | B19: =Model_Calculations!I121 -> 0.0072707372 | C19: =Model_Calculations!E121/Model_Calculations!E200 -> 0.012093191 | D19: =Model_Calculations!C121/Model_Calculations!C199 -> 0.00010196085 | P19: 18 | Q19: 62 | R19: 0.02896313 | S19: 72.240299
A20: 16 | B20: =Model_Calculations!I122 -> 0.0054725979 | C20: =Model_Calculations!E122/Model_Calculations!E200 -> 0.010021642 | D20: =Model_Calculations!C122/Model_Calculations!C199 -> 3.050067e-05 | P20: 19 | Q20: 54 | R20: 0.0072960501 | S20: 59.884832
A21: 17 | B21: =Model_Calculations!I123 -> 0.0042217184 | C21: =Model_Calculations!E123/Model_Calculations!E200 -> 0.0083059392 | D21: =Model_Calculations!C123/Model_Calculations!C199 -> 8.5872948e-06 | P21: 20 | Q21: 43 | R21: 0.0017460382 | S21: 49.646803
A22: 18 | B22: =Model_Calculations!I124 -> 0.0048471582 | C22: =Model_Calculations!E124/Model_Calculations!E200 -> 0.006884696 | D22: =Model_Calculations!C124/Model_Calculations!C199 -> 2.2833884e-06 | P22: 21 | Q22: 46 | R22: 0.0003979517 | S22: 41.162273
A23: 19 | B23: =Model_Calculations!I125 -> 0.0042217184 | C23: =Model_Calculations!E125/Model_Calculations!E200 -> 0.0057071866 | D23: =Model_Calculations!C125/Model_Calculations!C199 -> 5.7520428e-07 | P23: 22 | Q23: 44 | R23: 8.6577213e-05 | S23: 34.130131
A24: 20 | B24: =Model_Calculations!I126 -> 0.0033617387 | C24: =Model_Calculations!E126/Model_Calculations!E200 -> 0.0047314747 | D24: =Model_Calculations!C126/Model_Calculations!C199 -> 1.3765375e-07 | P24: 23 | Q24: 21 | R24: 1.8016552e-05 | S24: 28.301175
A25: 21 | B25: =Model_Calculations!I127 -> 0.0035962786 | C25: =Model_Calculations!E127/Model_Calculations!E200 -> 0.003922876 | D25: =Model_Calculations!C127/Model_Calculations!C199 -> 3.1373622e-08 | P25: 24 | Q25: 24 | R25: 3.5929929e-06 | S25: 23.469105
A26: 22 | B26: =Model_Calculations!I128 -> 0.0034399187 | C26: =Model_Calculations!E128/Model_Calculations!E200 -> 0.0032526939 | D26: =Model_Calculations!C128/Model_Calculations!C199 -> 6.8255539e-09 | P26: 25 | Q26: 22 | R26: 6.8787935e-07 | S26: 19.463105
A27: 23 | B27: =Model_Calculations!I129 -> 0.0016417794 | C27: =Model_Calculations!E129/Model_Calculations!E200 -> 0.0026971785 | D27: =Model_Calculations!C129/Model_Calculations!C199 -> 1.4203847e-09 | P27: 26 | Q27: 35 | R27: 1.2662949e-07 | S27: 16.141705
A28: 24 | B28: =Model_Calculations!I130 -> 0.0018763193 | C28: =Model_Calculations!E130/Model_Calculations!E200 -> 0.0022366692 | D28: =Model_Calculations!C130/Model_Calculations!C199 -> 2.8326353e-10 | P28: 27 | Q28: 21 | R28: 2.2447449e-08 | S28: 13.387726
A29: 25 | B29: =Model_Calculations!I131 -> 0.0017199593 | C29: =Model_Calculations!E131/Model_Calculations!E200 -> 0.0018548866 | D29: =Model_Calculations!C131/Model_Calculations!C199 -> 5.423087e-11 | P29: 28 | Q29: 21 | R29: 3.8371157e-09 | S29: 11.104088
P30: 29 | Q30: 19 | R30: 6.3329027e-10 | S30: 9.2103539
P31: 30 | Q31: 14 | R31: 1.0103631e-10 | S31: 7.6398701
P32: 31 | Q32: 22 | R32: 1.5599537e-11 | S32: 6.3373953
P33: 32 | Q33: 11 | R33: 2.3332305e-12 | S33: 5.2571437
P34: 33 | Q34: 8 | R34: 3.3840723e-13 | S34: 4.3611623
P35: 34 | Q35: 17 | R35: 4.7638341e-14 | S35: 3.6179889
P36: 35 | Q36: 9 | R36: 6.5145513e-15 | S36: 3.0015395
P37: 36 | Q37: 12 | R37: 8.6611972e-16 | S37: 2.4901878
P38: 37 | Q38: 10 | R38: 1.1203975e-16 | S38: 2.0660019
P39: 38 | Q39: 11 | R39: 1.4111866e-17 | S39: 1.7141127
P40: 39 | Q40: 4 | R40: 1.7318719e-18 | S40: 1.4221897
...
